<?xml version="1.0" encoding="utf-8"?>
<!-- =================================================================================== -->
<!-- |    This document was autogenerated by xacro from mini.xacro                     | -->
<!-- |    EDITING THIS FILE BY HAND IS NOT RECOMMENDED                                 | -->
<!-- =================================================================================== -->
<robot name="scout_mini">
  <!--    <xacro:property name="track" value="0.3426" />
    <xacro:property name="wheelbase" value="0.3181"/>
    <xacro:property name="wheel_vertical_offset" value="-0.160000047342231" />-->
  <!-- Base link -->
  <link name="base_link">
    <visual>
      <origin rpy="1.57 0 -1.57" xyz="0 0 0.0"/>
      <geometry>
        <mesh filename="package://scout_description/meshes/scout_mini_base_link2.dae"/>
      </geometry>
    </visual>
    <collision>
      <origin rpy="0 0 0" xyz="0 0 0"/>
      <geometry>
        <!--<mesh
              filename="package://scout_description/meshes/scout_mini_base_link2.dae" />-->
        <box size="0.514618 0.3816 0.10357"/>
      </geometry>
    </collision>
  </link>
  <!-- <joint name="chassis_link_joint" type="fixed">
        <origin xyz="0 0 ${wheel_radius - wheel_vertical_offset}" rpy="0 0 0" />
        <parent link="base_link" />
        <child link="chassis_link" />
    </joint> -->
  <link name="inertial_link">
    <inertial>
      <mass value="60"/>
      <origin xyz="0.0 0.0 0.0"/>
      <inertia ixx="2.288641" ixy="0" ixz="0" iyy="5.103976" iyz="0" izz="3.431465"/>
    </inertial>
  </link>
  <joint name="inertial_joint" type="fixed">
    <origin rpy="0 0 0" xyz="0 0 0"/>
    <parent link="base_link"/>
    <child link="inertial_link"/>
  </joint>
  <!-- For testing, hang the robot up in the air -->
  <!-- <link name="world" />
    <joint name="world_to_base_link=" type="fixed">
        <origin xyz="0 0 0.5" rpy="0 0 0" />
        <parent link="world"/>
        <child link="base_link"/>
    </joint> -->
  <link name="front_left_wheel_link">
    <!--<inertial>
                <mass value="3" />
                <origin
                        xyz="0.162297526351145 -0.159063056237197 -0.159999952657767"
                        rpy="0 0 0" />
                        <inertia ixx="0.7171" ixy="0" ixz="0" iyy="0.1361" iyz="0" izz="0.7171" />
                   </inertial>
            <visual>
                <origin xyz="0 0 0" rpy="0 0 0" />
                <geometry>
                    <mesh filename="package://scout_description/meshes/wheel.dae" />
                </geometry>
            </visual>-->
    <inertial>
      <mass value="15"/>
      <origin xyz="0 0 0"/>
      <inertia ixx="0.6171" ixy="0" ixz="0" iyy="0.6171" iyz="0" izz="0.1361"/>
      <!--<inertia ixx="0" ixy="0" ixz="0" iyy="0" iyz="0" izz="0" />-->
    </inertial>
    <visual>
      <origin rpy="0 0 0" xyz="0 0 0"/>
      <geometry>
        <mesh filename="package://scout_description/meshes/wheel.dae"/>
      </geometry>
    </visual>
    <collision>
      <origin rpy="0 0 0" xyz="0 0 0.04"/>
      <geometry>
        <!--<mesh
                  filename="package://scout_description/meshes/wheel.dae" />-->
        <cylinder length="0.08" radius="0.08"/>
      </geometry>
    </collision>
  </link>
  <joint name="front_left_wheel" type="continuous">
    <!--<origin
                  xyz="0.14547 0.20835 -0.07424"
                  rpy="0 1.57 0" />-->
    <parent link="base_link"/>
    <child link="front_left_wheel_link"/>
    <origin rpy="-1.57 0 0" xyz="0.2319755 0.2082515 -0.100998"/>
    <axis rpy="0 0 0" xyz="0 0 -1"/>
  </joint>
  <link name="rear_left_wheel_link">
    <!--<inertial>
            <mass value="3" />
                <origin
                        xyz="0.162297526351148 0.159063056237198 -0.160000047342231"
                        rpy="0 0 0" />
                        <inertia ixx="0.7171" ixy="0" ixz="0" iyy="0.1361" iyz="0" izz="0.7171" />
            </inertial>
            <visual>
                <origin xyz="0 0 0" rpy="0 0 0" />
                <geometry>
                    <mesh filename="package://scout_description/meshes/wheel.dae" />
                </geometry>
            </visual>-->
    <inertial>
      <mass value="15"/>
      <origin xyz="0 0 0"/>
      <inertia ixx="0.6171" ixy="0" ixz="0" iyy="0.6171" iyz="0" izz="0.1361"/>
      <!--<inertia ixx="0" ixy="0" ixz="0" iyy="0" iyz="0" izz="0" />-->
    </inertial>
    <visual>
      <origin rpy="0 0 0" xyz="0 0 0"/>
      <geometry>
        <mesh filename="package://scout_description/meshes/wheel.dae"/>
      </geometry>
    </visual>
    <collision>
      <origin rpy="0 0 0" xyz="0 0 0.04"/>
      <geometry>
        <!--<mesh
                  filename="package://scout_description/meshes/wheel.dae" />-->
        <cylinder length="0.08" radius="0.08"/>
      </geometry>
    </collision>
  </link>
  <joint name="rear_left_wheel" type="continuous">
    <!--<origin
                  xyz="-0.17453 0.20835 -0.07424"
                  rpy="0 -1.57 0" />-->
    <parent link="base_link"/>
    <child link="rear_left_wheel_link"/>
    <origin rpy="-1.57 0 0" xyz="-0.2319755 0.2082515 -0.100998"/>
    <axis rpy="0 0 0" xyz="0 0 -1"/>
  </joint>
  <link name="front_right_wheel_link">
    <!--<inertial>
            <mass value="3" />
                <origin
                        xyz="-0.235088020493741 -0.0575697183039213 -0.16000004734223"
                        rpy="0 0 0" />
                        <inertia ixx="0.7171" ixy="0" ixz="0" iyy="0.1361" iyz="0" izz="0.7171" />
            </inertial>
            <visual>
                <origin xyz="0 0 0" rpy="0 0 0" />
                <geometry>
                    <mesh filename="package://scout_description/meshes/wheel.dae" />
                </geometry>
            </visual>-->
    <inertial>
      <mass value="15"/>
      <origin xyz="0 0 0"/>
      <inertia ixx="0.6171" ixy="0" ixz="0" iyy="0.6171" iyz="0" izz="0.1361"/>
      <!--<inertia ixx="0" ixy="0" ixz="0" iyy="0" iyz="0" izz="0" />-->
    </inertial>
    <visual>
      <origin rpy="0 0 0" xyz="0 0 0"/>
      <geometry>
        <mesh filename="package://scout_description/meshes/wheel.dae"/>
      </geometry>
    </visual>
    <collision>
      <origin rpy="0 0 0" xyz="0 0 0.04"/>
      <geometry>
        <!--<mesh
                  filename="package://scout_description/meshes/wheel.dae" />-->
        <cylinder length="0.08" radius="0.08"/>
      </geometry>
    </collision>
  </link>
  <joint name="front_right_wheel" type="continuous">
    <!--<origin
                  xyz="-0.17453 -0.24424 -0.07424"
                  rpy="0 -1.57 0" />-->
    <parent link="base_link"/>
    <child link="front_right_wheel_link"/>
    <origin rpy="1.57 0 0" xyz="0.2319755 -0.2082515 -0.099998"/>
    <axis rpy="0 0 0" xyz="0 0 -1"/>
  </joint>
  <link name="rear_right_wheel_link">
    <!--<inertial>
        <mass value="3" />
            <origin
                    xyz="0.235244832119832 -0.0585653794466942 -0.206994929144493"
                    rpy="0 0 0" />
                    <inertia ixx="0.7171" ixy="0" ixz="0" iyy="0.1361" iyz="0" izz="0.7171" />
        </inertial>
        <visual>
            <origin xyz="0 0 0" rpy="0 0 0" />
            <geometry>
                <mesh filename="package://scout_description/meshes/wheel.dae" />
            </geometry>
        </visual>-->
    <inertial>
      <mass value="15"/>
      <origin xyz="0 0 0"/>
      <inertia ixx="0.6171" ixy="0" ixz="0" iyy="0.6171" iyz="0" izz="0.1361"/>
      <!--<inertia ixx="0" ixy="0" ixz="0" iyy="0" iyz="0" izz="0" />-->
    </inertial>
    <visual>
      <origin rpy="0 0 0" xyz="0 0 0"/>
      <geometry>
        <mesh filename="package://scout_description/meshes/wheel.dae"/>
      </geometry>
    </visual>
    <collision>
      <origin rpy="0 0 0" xyz="0 0 0.04"/>
      <geometry>
        <!--<mesh
                  filename="package://scout_description/meshes/wheel.dae" />-->
        <cylinder length="0.08" radius="0.08"/>
      </geometry>
    </collision>
  </link>
  <joint name="rear_right_wheel" type="continuous">
    <!--<origin
                  xyz="0.19247 -0.24486 -0.073441"
                  rpy="-0 1.57 0" />-->
    <parent link="base_link"/>
    <child link="rear_right_wheel_link"/>
    <origin rpy="1.57 0 0" xyz="-0.2319755 -0.2082515 -0.099998"/>
    <axis rpy="0 0 0" xyz="0 0 -1"/>
  </joint>
  <material name="aluminum">
    <color rgba="0.5 0.5 0.5 1"/>
  </material>
  <material name="plastic">
    <color rgba="0.1 0.1 0.1 1"/>
  </material>
  <!-- <link name="os_sensor" /> -->
  <!-- <link name="usb_cam"/> -->
  <!-- <link name="d435_link" /> -->
  <!-- t265 -->
  <link name="t265_pose_frame">
    <visual>
      <!-- still need to check if the actual output, if the rotation is just visual or... -->
      <origin rpy="1.5708 0 0" xyz="0 0 0.0"/>
      <geometry>
        <mesh filename="package://realsense2_description/meshes/t265.stl"/>
      </geometry>
      <material name="aluminum">
        <color rgba="0.5 0.5 0.5 1"/>
      </material>
    </visual>
  </link>
  <joint name="cam_link_t265" type="fixed">
    <origin rpy="0 0 0" xyz="0.18 0 0.10"/>
    <parent link="base_link"/>
    <child link="t265_pose_frame"/>
  </joint>
  <!-- camera body, with origin at bottom screw mount -->
  <joint name="d435_joint" type="fixed">
    <origin rpy="0 0 0" xyz="0.19 0 0.06"/>
    <parent link="base_link"/>
    <child link="d435_bottom_screw_frame"/>
  </joint>
  <link name="d435_bottom_screw_frame"/>
  <joint name="d435_link_joint" type="fixed">
    <origin rpy="0 0 0" xyz="0.0106 0.0175 0.0125"/>
    <parent link="d435_bottom_screw_frame"/>
    <child link="d435_link"/>
  </joint>
  <link name="d435_link">
    <visual>
      <!-- the mesh origin is at front plate in between the two infrared camera axes -->
      <origin rpy="1.57079632679 0 1.57079632679" xyz="0.0043 -0.0175 0"/>
      <geometry>
        <!-- <box size="${d435_cam_width} ${d435_cam_height} ${d435_cam_depth}"/> -->
        <mesh filename="package://realsense2_description/meshes/d435.dae"/>
      </geometry>
    </visual>
    <collision>
      <origin rpy="0 0 0" xyz="0 -0.0175 0"/>
      <geometry>
        <box size="0.02505 0.09 0.025"/>
      </geometry>
    </collision>
    <inertial>
      <!-- The following are not reliable values, and should not be used for modeling -->
      <mass value="0.072"/>
      <origin xyz="0 0 0"/>
      <inertia ixx="0.003881243" ixy="0.0" ixz="0.0" iyy="0.000498940" iyz="0.0" izz="0.003879257"/>
    </inertial>
  </link>
  <!--Velodyne and Velodyne Interface -->
  <link name="velodyne_mount"/>
  <joint name="velodyne_mount_joint" type="fixed">
    <parent link="base_link"/>
    <child link="velodyne_mount"/>
    <origin rpy="0 0 0" xyz="0.1 0 0.17"/>
  </joint>
  <joint name="velodyne_base_mount_joint" type="fixed">
    <origin rpy="0 0 0" xyz="0 0 0"/>
    <parent link="velodyne_mount"/>
    <child link="velodyne_base_link"/>
  </joint>
  <link name="velodyne_base_link">
    <inertial>
      <mass value="0.83"/>
      <origin xyz="0 0 0.03585"/>
      <inertia ixx="0.000908059425" ixy="0" ixz="0" iyy="0.000908059425" iyz="0" izz="0.0011049624"/>
    </inertial>
    <visual>
      <geometry>
        <mesh filename="package://velodyne_description/meshes/VLP16_base_1.dae"/>
      </geometry>
    </visual>
    <visual>
      <geometry>
        <mesh filename="package://velodyne_description/meshes/VLP16_base_2.dae"/>
      </geometry>
    </visual>
    <collision>
      <origin rpy="0 0 0" xyz="0 0 0.03585"/>
      <geometry>
        <cylinder length="0.0717" radius="0.0516"/>
      </geometry>
    </collision>
  </link>
  <joint name="velodyne_base_scan_joint" type="fixed">
    <origin rpy="0 0 0" xyz="0 0 0.0377"/>
    <parent link="velodyne_base_link"/>
    <child link="velodyne"/>
  </joint>
  <link name="velodyne">
    <inertial>
      <mass value="0.01"/>
      <origin xyz="0 0 0"/>
      <inertia ixx="1e-7" ixy="0" ixz="0" iyy="1e-7" iyz="0" izz="1e-7"/>
    </inertial>
    <visual>
      <origin xyz="0 0 -0.0377"/>
      <geometry>
        <mesh filename="package://velodyne_description/meshes/VLP16_scan.dae"/>
      </geometry>
    </visual>
  </link>
  <!-- Gazebo requires the velodyne_gazebo_plugins package -->
  <gazebo reference="velodyne">
    <sensor name="velodyne-VLP16" type="ray">
      <pose>0 0 0 0 0 0</pose>
      <visualize>false</visualize>
      <update_rate>10</update_rate>
      <ray>
        <scan>
          <horizontal>
            <samples>440</samples>
            <resolution>1</resolution>
            <min_angle>-3.14159265359</min_angle>
            <max_angle>3.14159265359</max_angle>
          </horizontal>
          <vertical>
            <samples>16</samples>
            <resolution>1</resolution>
            <min_angle>-0.261799387799</min_angle>
            <max_angle> 0.261799387799</max_angle>
          </vertical>
        </scan>
        <range>
          <min>0.3</min>
          <max>131.0</max>
          <resolution>0.001</resolution>
        </range>
        <noise>
          <type>gaussian</type>
          <mean>0.0</mean>
          <stddev>0.0</stddev>
        </noise>
      </ray>
      <plugin filename="libgazebo_ros_velodyne_laser.so" name="gazebo_ros_laser_controller">
        <topicName>/velodyne_points</topicName>
        <frameName>velodyne</frameName>
        <organize_cloud>False</organize_cloud>
        <min_range>0.9</min_range>
        <max_range>130.0</max_range>
        <gaussianNoise>0.008</gaussianNoise>
      </plugin>
    </sensor>
  </gazebo>
  <link name="gx5_link"/>
  <joint name="microstrain_joint" type="fixed">
    <parent link="velodyne_mount"/>
    <child link="gx5_link"/>
    <origin rpy="0 0 0" xyz="-0.015 0 -0.113"/>
  </joint>

   <link name="tracking_link"/>
  <joint name="tracking_joint" type="fixed">
    <child link="tracking_link"/>
    <parent link="gx5_link"/>
    <origin rpy="0 0 0" xyz="0 0 0"/>
  </joint>
  <!-- Additional definitions for simulation -->
  <!-- <gazebo reference="base_link">
        <material>Gazebo/Grey</material>
    </gazebo> -->
  <transmission name="front_right_wheel_trans" type="SimpleTransmission">
    <type>transmission_interface/SimpleTransmission</type>
    <actuator name="front_right_wheel_motor">
      <mechanicalReduction>1</mechanicalReduction>
    </actuator>
    <joint name="front_right_wheel">
      <hardwareInterface>hardware_interface/VelocityJointInterface</hardwareInterface>
    </joint>
  </transmission>
  <transmission name="front_left_wheel_trans" type="SimpleTransmission">
    <type>transmission_interface/SimpleTransmission</type>
    <actuator name="front_left_wheel_motor">
      <mechanicalReduction>1</mechanicalReduction>
    </actuator>
    <joint name="front_left_wheel">
      <hardwareInterface>hardware_interface/VelocityJointInterface</hardwareInterface>
    </joint>
  </transmission>
  <transmission name="rear_left_wheel_trans" type="SimpleTransmission">
    <type>transmission_interface/SimpleTransmission</type>
    <actuator name="rear_left_wheel_motor">
      <mechanicalReduction>1</mechanicalReduction>
    </actuator>
    <joint name="rear_left_wheel">
      <hardwareInterface>hardware_interface/VelocityJointInterface</hardwareInterface>
    </joint>
  </transmission>
  <transmission name="rear_right_wheel_trans" type="SimpleTransmission">
    <type>transmission_interface/SimpleTransmission</type>
    <actuator name="rear_right_wheel_motor">
      <mechanicalReduction>1</mechanicalReduction>
    </actuator>
    <joint name="rear_right_wheel">
      <hardwareInterface>hardware_interface/VelocityJointInterface</hardwareInterface>
    </joint>
  </transmission>
  <!-- Controller configurations -->
  <gazebo>
    <plugin filename="libgazebo_ros_control.so" name="gazebo_ros_control">
      <robotNamespace>/</robotNamespace>
    </plugin>
  </gazebo>
  <!-- kp spring constant, kd damping constant -->
  <gazebo>
    <mu1 value="1.0"/>
    <mu2 value="0.9"/>
    <kp value="10000000.0"/>
    <kd value="1.0"/>
    <fdir1 value="1 0 0"/>
    <minDepth value="0.001"/>
    <maxContacts value="64"/>
  </gazebo>
  <!-- <gazebo>
        <plugin name="skid_steer_drive_controller" filename="libgazebo_ros_skid_steer_drive.so">
            <updateRate>100.0</updateRate>
            <robotNamespace></robotNamespace>
            <leftFrontJoint>front_left_wheel</leftFrontJoint>
            <rightFrontJoint>front_right_wheel</rightFrontJoint>
            <leftRearJoint>rear_left_wheel</leftRearJoint>
            <rightRearJoint>rear_right_wheel</rightRearJoint>
            <wheelSeparation>4</wheelSeparation>
            <wheelDiameter>0.32918</wheelDiameter>
            <robotBaseFrame>base_link</robotBaseFrame>
            <torque>1000</torque>
            <commandTopic>cmd_vel</commandTopic>
            <broadcastTF>true</broadcastTF>
            <odometryTopic>odom</odometryTopic>
            <odometryFrame>odom</odometryFrame>
            <covariance_x>0.000100</covariance_x>
            <covariance_y>0.000100</covariance_y>
            <covariance_yaw>0.010000</covariance_yaw>
        </plugin>
    </gazebo> -->
  <!-- <gazebo>
        <plugin name="object_controller" filename="libgazebo_ros_planar_move.so">
            <commandTopic>cmd_vel</commandTopic>
            <odometryTopic>odom</odometryTopic>
            <odometryFrame>odom</odometryFrame>
            <odometryRate>20.0</odometryRate>
            <robotBaseFrame>base_footprint</robotBaseFrame>
        </plugin>
    </gazebo> -->
</robot>

